[2023-02-11T06:01:04.044+0000] {taskinstance.py:1083} INFO - Dependencies all met for <TaskInstance: dag_pg_op.create_table scheduled__2023-02-09T06:01:00+00:00 [queued]>
[2023-02-11T06:01:04.063+0000] {taskinstance.py:1083} INFO - Dependencies all met for <TaskInstance: dag_pg_op.create_table scheduled__2023-02-09T06:01:00+00:00 [queued]>
[2023-02-11T06:01:04.063+0000] {taskinstance.py:1279} INFO - 
--------------------------------------------------------------------------------
[2023-02-11T06:01:04.063+0000] {taskinstance.py:1280} INFO - Starting attempt 1 of 6
[2023-02-11T06:01:04.063+0000] {taskinstance.py:1281} INFO - 
--------------------------------------------------------------------------------
[2023-02-11T06:01:04.080+0000] {taskinstance.py:1300} INFO - Executing <Task(PostgresOperator): create_table> on 2023-02-09 06:01:00+00:00
[2023-02-11T06:01:04.085+0000] {standard_task_runner.py:55} INFO - Started process 7257 to run task
[2023-02-11T06:01:04.088+0000] {standard_task_runner.py:82} INFO - Running: ['***', 'tasks', 'run', 'dag_pg_op', 'create_table', 'scheduled__2023-02-09T06:01:00+00:00', '--job-id', '68', '--raw', '--subdir', 'DAGS_FOLDER/dag_with_pg_op.py', '--cfg-path', '/tmp/tmp77ivtd9x']
[2023-02-11T06:01:04.089+0000] {standard_task_runner.py:83} INFO - Job 68: Subtask create_table
[2023-02-11T06:01:04.157+0000] {task_command.py:388} INFO - Running <TaskInstance: dag_pg_op.create_table scheduled__2023-02-09T06:01:00+00:00 [running]> on host 61856ed39d63
[2023-02-11T06:01:04.229+0000] {taskinstance.py:1509} INFO - Exporting the following env vars:
AIRFLOW_CTX_DAG_OWNER=naufal
AIRFLOW_CTX_DAG_ID=dag_pg_op
AIRFLOW_CTX_TASK_ID=create_table
AIRFLOW_CTX_EXECUTION_DATE=2023-02-09T06:01:00+00:00
AIRFLOW_CTX_TRY_NUMBER=1
AIRFLOW_CTX_DAG_RUN_ID=scheduled__2023-02-09T06:01:00+00:00
[2023-02-11T06:01:04.230+0000] {sql.py:254} INFO - Executing: 
            CREATE TABLE IF NOT EXITS dag_runs (
                dt date,
                dag_id character varying,
                primary key (dt,dag_id)
            );
        
[2023-02-11T06:01:04.238+0000] {base.py:73} INFO - Using connection ID 'pg_localhost' for task execution.
[2023-02-11T06:01:04.473+0000] {base.py:73} INFO - Using connection ID 'pg_localhost' for task execution.
[2023-02-11T06:01:04.683+0000] {taskinstance.py:1768} ERROR - Task failed with exception
Traceback (most recent call last):
  File "/home/airflow/.local/lib/python3.7/site-packages/airflow/providers/common/sql/operators/sql.py", line 266, in execute
    **extra_kwargs,
  File "/home/airflow/.local/lib/python3.7/site-packages/airflow/providers/common/sql/hooks/sql.py", line 342, in run
    with closing(self.get_conn()) as conn:
  File "/home/airflow/.local/lib/python3.7/site-packages/airflow/providers/postgres/hooks/postgres.py", line 144, in get_conn
    self.conn = psycopg2.connect(**conn_args)
  File "/home/airflow/.local/lib/python3.7/site-packages/psycopg2/__init__.py", line 122, in connect
    conn = _connect(dsn, connection_factory=connection_factory, **kwasync)
psycopg2.OperationalError: connection to server at "host.docker.internal" (36.86.63.182), port 5432 failed: Connection refused
	Is the server running on that host and accepting TCP/IP connections?

[2023-02-11T06:01:04.697+0000] {taskinstance.py:1323} INFO - Marking task as UP_FOR_RETRY. dag_id=dag_pg_op, task_id=create_table, execution_date=20230209T060100, start_date=20230211T060104, end_date=20230211T060104
[2023-02-11T06:01:04.722+0000] {standard_task_runner.py:105} ERROR - Failed to execute job 68 for task create_table (connection to server at "host.docker.internal" (36.86.63.182), port 5432 failed: Connection refused
	Is the server running on that host and accepting TCP/IP connections?
; 7257)
[2023-02-11T06:01:04.744+0000] {local_task_job.py:208} INFO - Task exited with return code 1
[2023-02-11T06:01:04.761+0000] {taskinstance.py:2578} INFO - 0 downstream tasks scheduled from follow-on schedule check
